[nltk_data] Downloading package punkt to /home/rachid/nltk_data...
[nltk_data]   Package punkt is already up-to-date!
[nltk_data] Downloading package stopwords to /home/rachid/nltk_data...
[nltk_data]   Package stopwords is already up-to-date!
Traceback (most recent call last):
  File "/mnt/c/Users/faska/Documents/School/IG5/PFE/Projectly-api-rag/api/app.py", line 14, in <module>
    init_es_db(client)
  File "/mnt/c/Users/faska/Documents/School/IG5/PFE/Projectly-api-rag/api/functions.py", line 14, in init_es_db
    if not client.indices.exists(index="projectly"):
           ^^^^^^^^^^^^^^^^^^^^^^^^^^^^^^^^^^^^^^^^
  File "/home/linuxbrew/.linuxbrew/Cellar/python@3.11/3.11.6_1/lib/python3.11/site-packages/elasticsearch/_sync/client/utils.py", line 402, in wrapped
    return api(*args, **kwargs)
           ^^^^^^^^^^^^^^^^^^^^
  File "/home/linuxbrew/.linuxbrew/Cellar/python@3.11/3.11.6_1/lib/python3.11/site-packages/elasticsearch/_sync/client/indices.py", line 1100, in exists
    return self.perform_request(  # type: ignore[return-value]
           ^^^^^^^^^^^^^^^^^^^^^^^^^^^^^^^^^^^^^^^^^^^^^^^^^^^
  File "/home/linuxbrew/.linuxbrew/Cellar/python@3.11/3.11.6_1/lib/python3.11/site-packages/elasticsearch/_sync/client/_base.py", line 389, in perform_request
    return self._client.perform_request(
           ^^^^^^^^^^^^^^^^^^^^^^^^^^^^^
  File "/home/linuxbrew/.linuxbrew/Cellar/python@3.11/3.11.6_1/lib/python3.11/site-packages/elasticsearch/_sync/client/_base.py", line 285, in perform_request
    meta, resp_body = self.transport.perform_request(
                      ^^^^^^^^^^^^^^^^^^^^^^^^^^^^^^^
  File "/home/linuxbrew/.linuxbrew/Cellar/python@3.11/3.11.6_1/lib/python3.11/site-packages/elastic_transport/_transport.py", line 328, in perform_request
    meta, raw_data = node.perform_request(
                     ^^^^^^^^^^^^^^^^^^^^^
  File "/home/linuxbrew/.linuxbrew/Cellar/python@3.11/3.11.6_1/lib/python3.11/site-packages/elastic_transport/_node/_http_urllib3.py", line 202, in perform_request
    raise err from None
elastic_transport.ConnectionError: Connection error caused by: ConnectionError(Connection error caused by: NewConnectionError(<urllib3.connection.HTTPConnection object at 0x7fcf65290b50>: Failed to establish a new connection: [Errno 111] Connection refused))
[nltk_data] Downloading package punkt to /home/rachid/nltk_data...
[nltk_data]   Package punkt is already up-to-date!
[nltk_data] Downloading package stopwords to /home/rachid/nltk_data...
[nltk_data]   Package stopwords is already up-to-date!
Traceback (most recent call last):
  File "/mnt/c/Users/faska/Documents/School/IG5/PFE/Projectly-api-rag/api/app.py", line 14, in <module>
    init_es_db(client)
  File "/mnt/c/Users/faska/Documents/School/IG5/PFE/Projectly-api-rag/api/functions.py", line 14, in init_es_db
    if not client.indices.exists(index="projectly"):
           ^^^^^^^^^^^^^^^^^^^^^^^^^^^^^^^^^^^^^^^^
  File "/home/linuxbrew/.linuxbrew/Cellar/python@3.11/3.11.6_1/lib/python3.11/site-packages/elasticsearch/_sync/client/utils.py", line 402, in wrapped
    return api(*args, **kwargs)
           ^^^^^^^^^^^^^^^^^^^^
  File "/home/linuxbrew/.linuxbrew/Cellar/python@3.11/3.11.6_1/lib/python3.11/site-packages/elasticsearch/_sync/client/indices.py", line 1100, in exists
    return self.perform_request(  # type: ignore[return-value]
           ^^^^^^^^^^^^^^^^^^^^^^^^^^^^^^^^^^^^^^^^^^^^^^^^^^^
  File "/home/linuxbrew/.linuxbrew/Cellar/python@3.11/3.11.6_1/lib/python3.11/site-packages/elasticsearch/_sync/client/_base.py", line 389, in perform_request
    return self._client.perform_request(
           ^^^^^^^^^^^^^^^^^^^^^^^^^^^^^
  File "/home/linuxbrew/.linuxbrew/Cellar/python@3.11/3.11.6_1/lib/python3.11/site-packages/elasticsearch/_sync/client/_base.py", line 285, in perform_request
    meta, resp_body = self.transport.perform_request(
                      ^^^^^^^^^^^^^^^^^^^^^^^^^^^^^^^
  File "/home/linuxbrew/.linuxbrew/Cellar/python@3.11/3.11.6_1/lib/python3.11/site-packages/elastic_transport/_transport.py", line 328, in perform_request
    meta, raw_data = node.perform_request(
                     ^^^^^^^^^^^^^^^^^^^^^
  File "/home/linuxbrew/.linuxbrew/Cellar/python@3.11/3.11.6_1/lib/python3.11/site-packages/elastic_transport/_node/_http_urllib3.py", line 202, in perform_request
    raise err from None
elastic_transport.ConnectionError: Connection error caused by: ConnectionError(Connection error caused by: NewConnectionError(<urllib3.connection.HTTPConnection object at 0x7fd897ee7c90>: Failed to establish a new connection: [Errno 111] Connection refused))
[nltk_data] Downloading package punkt to /home/rachid/nltk_data...
[nltk_data]   Package punkt is already up-to-date!
[nltk_data] Downloading package stopwords to /home/rachid/nltk_data...
[nltk_data]   Package stopwords is already up-to-date!
Traceback (most recent call last):
  File "/mnt/c/Users/faska/Documents/School/IG5/PFE/Projectly-api-rag/api/app.py", line 14, in <module>
    init_es_db(client)
  File "/mnt/c/Users/faska/Documents/School/IG5/PFE/Projectly-api-rag/api/functions.py", line 14, in init_es_db
    if not client.indices.exists(index="projectly"):
           ^^^^^^^^^^^^^^^^^^^^^^^^^^^^^^^^^^^^^^^^
  File "/home/linuxbrew/.linuxbrew/Cellar/python@3.11/3.11.6_1/lib/python3.11/site-packages/elasticsearch/_sync/client/utils.py", line 402, in wrapped
    return api(*args, **kwargs)
           ^^^^^^^^^^^^^^^^^^^^
  File "/home/linuxbrew/.linuxbrew/Cellar/python@3.11/3.11.6_1/lib/python3.11/site-packages/elasticsearch/_sync/client/indices.py", line 1100, in exists
    return self.perform_request(  # type: ignore[return-value]
           ^^^^^^^^^^^^^^^^^^^^^^^^^^^^^^^^^^^^^^^^^^^^^^^^^^^
  File "/home/linuxbrew/.linuxbrew/Cellar/python@3.11/3.11.6_1/lib/python3.11/site-packages/elasticsearch/_sync/client/_base.py", line 389, in perform_request
    return self._client.perform_request(
           ^^^^^^^^^^^^^^^^^^^^^^^^^^^^^
  File "/home/linuxbrew/.linuxbrew/Cellar/python@3.11/3.11.6_1/lib/python3.11/site-packages/elasticsearch/_sync/client/_base.py", line 285, in perform_request
    meta, resp_body = self.transport.perform_request(
                      ^^^^^^^^^^^^^^^^^^^^^^^^^^^^^^^
  File "/home/linuxbrew/.linuxbrew/Cellar/python@3.11/3.11.6_1/lib/python3.11/site-packages/elastic_transport/_transport.py", line 328, in perform_request
    meta, raw_data = node.perform_request(
                     ^^^^^^^^^^^^^^^^^^^^^
  File "/home/linuxbrew/.linuxbrew/Cellar/python@3.11/3.11.6_1/lib/python3.11/site-packages/elastic_transport/_node/_http_urllib3.py", line 202, in perform_request
    raise err from None
elastic_transport.ConnectionError: Connection error caused by: ConnectionError(Connection error caused by: NewConnectionError(<urllib3.connection.HTTPConnection object at 0x7fa33d957e50>: Failed to establish a new connection: [Errno 111] Connection refused))
[nltk_data] Downloading package punkt to /home/rachid/nltk_data...
[nltk_data]   Package punkt is already up-to-date!
[nltk_data] Downloading package stopwords to /home/rachid/nltk_data...
[nltk_data]   Package stopwords is already up-to-date!
Traceback (most recent call last):
  File "/mnt/c/Users/faska/Documents/School/IG5/PFE/Projectly-api-rag/api/app.py", line 14, in <module>
    init_es_db(client)
  File "/mnt/c/Users/faska/Documents/School/IG5/PFE/Projectly-api-rag/api/functions.py", line 14, in init_es_db
    if not client.indices.exists(index="projectly"):
           ^^^^^^^^^^^^^^^^^^^^^^^^^^^^^^^^^^^^^^^^
  File "/home/linuxbrew/.linuxbrew/Cellar/python@3.11/3.11.6_1/lib/python3.11/site-packages/elasticsearch/_sync/client/utils.py", line 402, in wrapped
    return api(*args, **kwargs)
           ^^^^^^^^^^^^^^^^^^^^
  File "/home/linuxbrew/.linuxbrew/Cellar/python@3.11/3.11.6_1/lib/python3.11/site-packages/elasticsearch/_sync/client/indices.py", line 1100, in exists
    return self.perform_request(  # type: ignore[return-value]
           ^^^^^^^^^^^^^^^^^^^^^^^^^^^^^^^^^^^^^^^^^^^^^^^^^^^
  File "/home/linuxbrew/.linuxbrew/Cellar/python@3.11/3.11.6_1/lib/python3.11/site-packages/elasticsearch/_sync/client/_base.py", line 389, in perform_request
    return self._client.perform_request(
           ^^^^^^^^^^^^^^^^^^^^^^^^^^^^^
  File "/home/linuxbrew/.linuxbrew/Cellar/python@3.11/3.11.6_1/lib/python3.11/site-packages/elasticsearch/_sync/client/_base.py", line 285, in perform_request
    meta, resp_body = self.transport.perform_request(
                      ^^^^^^^^^^^^^^^^^^^^^^^^^^^^^^^
  File "/home/linuxbrew/.linuxbrew/Cellar/python@3.11/3.11.6_1/lib/python3.11/site-packages/elastic_transport/_transport.py", line 328, in perform_request
    meta, raw_data = node.perform_request(
                     ^^^^^^^^^^^^^^^^^^^^^
  File "/home/linuxbrew/.linuxbrew/Cellar/python@3.11/3.11.6_1/lib/python3.11/site-packages/elastic_transport/_node/_http_urllib3.py", line 202, in perform_request
    raise err from None
elastic_transport.ConnectionError: Connection error caused by: ConnectionError(Connection error caused by: NewConnectionError(<urllib3.connection.HTTPConnection object at 0x7f802e35a850>: Failed to establish a new connection: [Errno 111] Connection refused))
[nltk_data] Downloading package punkt to /home/rachid/nltk_data...
[nltk_data]   Package punkt is already up-to-date!
[nltk_data] Downloading package stopwords to /home/rachid/nltk_data...
[nltk_data]   Package stopwords is already up-to-date!
Traceback (most recent call last):
  File "/mnt/c/Users/faska/Documents/School/IG5/PFE/Projectly-api-rag/api/app.py", line 14, in <module>
    init_es_db(client)
  File "/mnt/c/Users/faska/Documents/School/IG5/PFE/Projectly-api-rag/api/functions.py", line 14, in init_es_db
    if not client.indices.exists(index="projectly"):
           ^^^^^^^^^^^^^^^^^^^^^^^^^^^^^^^^^^^^^^^^
  File "/home/linuxbrew/.linuxbrew/Cellar/python@3.11/3.11.6_1/lib/python3.11/site-packages/elasticsearch/_sync/client/utils.py", line 402, in wrapped
    return api(*args, **kwargs)
           ^^^^^^^^^^^^^^^^^^^^
  File "/home/linuxbrew/.linuxbrew/Cellar/python@3.11/3.11.6_1/lib/python3.11/site-packages/elasticsearch/_sync/client/indices.py", line 1100, in exists
    return self.perform_request(  # type: ignore[return-value]
           ^^^^^^^^^^^^^^^^^^^^^^^^^^^^^^^^^^^^^^^^^^^^^^^^^^^
  File "/home/linuxbrew/.linuxbrew/Cellar/python@3.11/3.11.6_1/lib/python3.11/site-packages/elasticsearch/_sync/client/_base.py", line 389, in perform_request
    return self._client.perform_request(
           ^^^^^^^^^^^^^^^^^^^^^^^^^^^^^
  File "/home/linuxbrew/.linuxbrew/Cellar/python@3.11/3.11.6_1/lib/python3.11/site-packages/elasticsearch/_sync/client/_base.py", line 285, in perform_request
    meta, resp_body = self.transport.perform_request(
                      ^^^^^^^^^^^^^^^^^^^^^^^^^^^^^^^
  File "/home/linuxbrew/.linuxbrew/Cellar/python@3.11/3.11.6_1/lib/python3.11/site-packages/elastic_transport/_transport.py", line 328, in perform_request
    meta, raw_data = node.perform_request(
                     ^^^^^^^^^^^^^^^^^^^^^
  File "/home/linuxbrew/.linuxbrew/Cellar/python@3.11/3.11.6_1/lib/python3.11/site-packages/elastic_transport/_node/_http_urllib3.py", line 202, in perform_request
    raise err from None
elastic_transport.ConnectionError: Connection error caused by: ConnectionError(Connection error caused by: NewConnectionError(<urllib3.connection.HTTPConnection object at 0x7f0d75b9bb50>: Failed to establish a new connection: [Errno 111] Connection refused))
